Workbook
Name Applicable: [1]Fields!$A$2:$A$3
Name Applicable: 'Fields & Revisions'!$A$2:$A$3
Name Assessor: 'Fields & Revisions'!#REF!
Name Five: 'Fields & Revisions'!#REF!
Name Ten: 'Fields & Revisions'!#REF!
Name Yes: [1]Fields!$B$2:$B$6
Name Yes: 'Fields & Revisions'!$B$2:$B$6

Sheet Intro
B2: Assessed Entity Name
B3: HITRUST CSF Validated Assessment
B4: Fieldwork: xx/xx/xxxx - xx/xx/xxxx
B6: Role | C6: Name
B7: Certified Assessor:
B8: Engagement Manager:
B9: Engagement QA: | C9: Angie Jones/James Whitfield
B10: Engagement Executive: | C10: Shreesh Bhattarai/James Whitfield
B12: Sample Sizes Guidance
B13: Manual Control | C13: 10% with a minimum of 3 and a maximum of 25
B14: Automatic Control | C14: Configuration and one example
B15: Periodic Rates | C15: Annual – Most recent report
C16: Quarterly – Sample of two quarters
C17: Monthly – Sample of two months
C18: Weekly – Sample of 5 weeks
C19: Daily – Sample of 25 days
B20: Sampling Methodology | C20: Random

Sheet Assessment
A1: IQA Review Notes | B1: IQA Review Responses | C1: Control Prisma Score | D1: CAP (Yes/No) | E1: In Scope | F1: Domain Name | G1: CVID | H1: Unique ID | I1: Level | J1: Control Reference | K1: Requirement Statement | L1: Implemented Guidance | M1: Implemented Guidance: Notes | N1: Sample Suggested | O1: Shared Responsibility Matrix (SRM) v9.x | P1: Inherited Weight | Q1: Score After Inheritance Applied: Policy | R1: Score After Inheritance Applied: Process | S1: Score After Inheritance Applied: Implementation | T1: Score After Inheritance Applied: Measured | U1: Score After Inheritance Applied: Managed | V1: Control Applicable | W1: N/A Reason | X1: Maturity - Policy | Y1: Maturity - Process | Z1: Maturity - Implemented | AA1: Maturity - Measured | AB1: Maturity - Managed | AC1: Policy File Name | AD1: Policy Mapping (policy name - page/section reference) | AE1: Policy exception notes (gap or defect)Two condition rules applied | AF1: Policy Reviewed By | AG1: Process File Name | AH1: Process Mapping (policy name - page/section reference) | AI1: Process exception notes (gap or defect)Two condition rules applied | AJ1: Process Reviewed By | AK1: Implemented inquiry contact (Name - Title) | AL1: Implemented inquiry notes | AM1: Implemented Observation notes | AN1: Implemented Evidence reviewed | AO1: Implemented Notes - what's in the file and how does it address the requirement? | AP1: Implemented exception notes (gap or defect) | AQ1: Inheritance Notes - explain weight rational | AR1: Date Control Was Scored/Tested | AS1: Implemented Reviewed By | AT1: Measure/Metrix evidence reviewed | AU1: Measure/Metrix evidence explanation and notes | AV1: Measure/Metrix Management evidence reviewed | AW1: Measure/Metrix Management evidence explanation and notes | AX1: Date Write-up Helper | AY1: Inheritance Write-up Helper (if needed) | AZ1: Policy Write-up Helper | BA1: Process Write-up Helper | BB1: Inquiry Write-up Helper(if needed) | BC1: Observation Write-up Helper(if needed) | BD1: Implemented (evidence) Write-up Helper | BE1: Measured Write-up Helper | BF1: Managed Write-up Helper | BG1: Sample Write-up Helper | BH1: Completed Full Comments
C2: =IF(V2="No","Not Applicable",(IF(X2="1. Non Compliant (0%)","0",IF(X2="2. Somewhat Compliant (25%)","25",IF(X2="3. Partially Compliant (50%)","50",IF(X2="4. Mostly Compliant (75%)","75",IF(X2="5. Fully Compliant (100%)","100")))))*0.15)+((IF(Y2="1. Non Compliant (0%)","0",IF(Y2="2. Somewhat Compliant (25%)","25",IF(Y2="3. Partially Compliant (50%)","50",IF(Y2="4. Mostly Compliant (75%)","75",IF(Y2="5. Fully Compliant (100%)","100"))))))*0.2)+(IF(Z2="1. Non Compliant (0%)","0",IF(Z2="2. Somewhat Compliant (25%)","25",IF(Z2="3. Partially Compliant (50%)","50",IF(Z2="4. Mostly Compliant (75%)","75",IF(Z2="5. Fully Compliant (100%)","100")))))*0.4)+(IF(AA2="1. Non Compliant (0%)","0",IF(AA2="2. Somewhat Compliant (25%)","25",IF(AA2="3. Partially Compliant (50%)","50",IF(AA2="4. Mostly Compliant (75%)","75",IF(AA2="5. Fully Compliant (100%)","100")))))*0.1)+(IF(AB2="1. Non Compliant (0%)","0",IF(AB2="2. Somewhat Compliant (25%)","25",IF(AB2="3. Partially Compliant (50%)","50",IF(AB2="4. Mostly Compliant (75%)","75",IF(AB2="5. Fully Compliant (100%)","100")))))*0.15)) -> 0 | D2: =IF(AND((_xlfn.XLOOKUP(J2,'Fields & Revisions'!$H:$H,'Fields & Revisions'!$I:$I))<70.99,(OR(Z2="4. Mostly Compliant (75%)",Z2="3. Partially Compliant (50%)",Z2="2. Somewhat Compliant (25%)",Z2="1. Non Compliant (0%)"))),"Yes","No") -> Yes | E2: =IF(ISERROR(VLOOKUP(H2,Scope!A:A,1,FALSE)),"No","Yes") -> Yes | F2: 01 Information Protection Program | G2: 3038.0 | H2: 01.00aAISecOrganizational.1 | I2: HITRUST Security for AI System | J2: 00.a Information Security Management Program | K2: As appropriate to the organization’s AI deployment context, the stated scope and contents of the organization’s written policies, in areas including but not limited to |security administration, |data governance, |software development, |risk management, |incident management, |business continuity, and |disaster recovery,|| explicitly includes the organization’s AI systems and their AI specificities.|| | L2: Examine evidence that all evaluative elements within the requirement statement have been implemented as defined in the HITRUST scoring rubric, using a sample based test where possible for each evaluative element. Example test(s): For example, review the organizations written policies for AI systems to confirm their completeness. Further, confirm that the AI system policies contain security administration, data governance, software development, risk management, incident management, business continuity, and disaster recovery, explicitly to AI systems and their AI specificities. | M2: Documentation: Artificial Intelligence Program - defines: security administration - defines: data governance - defines: software development - defines: risk management - defines: incident management - defines: business continuity - defines: disaster recovery | N2: No | O2: =_xlfn.XLOOKUP(G2,SRMs!$A:$A,SRMs!$D:$D) -> NO INHERITANCE | P2: =IFERROR(VLOOKUP(H2,Inherited!A:B,2,FALSE),"") | Q2: =IF(MATCH(H2,Inherited!A:A),IF((((_xlfn.XLOOKUP(Assessment!#REF!,Inherited!A:A,Inherited!B:B))/100)*(_xlfn.XLOOKUP(Assessment!#REF!,Inherited!A:A,Inherited!C:C)))+(((100-(_xlfn.XLOOKUP(Assessment!#REF!,Inherited!A:A,Inherited!B:B)))/100)*IF(X2="1. Non Compliant (0%)","0",IF(X2="2. Somewhat Compliant (25%)","25",IF(X2="3. Partially Compliant (50%)","50",IF(X2="4. Mostly Compliant (75%)","75",IF(X2="5. Fully Compliant (100%)","100"))))))<=10,"0", IF(AND((((_xlfn.XLOOKUP(Assessment!#REF!,Inherited!A:A,Inherited!B:B))/100)*(_xlfn.XLOOKUP(Assessment!#REF!,Inherited!A:A,Inherited!C:C)))+(((100-(_xlfn.XLOOKUP(Assessment!#REF!,Inherited!A:A,Inherited!B:B)))/100)*IF(X2="1. Non Compliant (0%)","0",IF(X2="2. Somewhat Compliant (25%)","25",IF(X2="3. Partially Compliant (50%)","50",IF(X2="4. Mostly Compliant (75%)","75",IF(X2="5. Fully Compliant (100%)","100"))))))>=11,(((_xlfn.XLOOKUP(Assessment!#REF!,Inherited!A:A,Inherited!B:B))/100)*(_xlfn.XLOOKUP(Assessment!#REF!,Inherited!A:A,Inherited!C:C)))+(((100-(_xlfn.XLOOKUP(Assessment!#REF!,Inherited!A:A,Inherited!B:B)))/100)*IF(X2="1. Non Compliant (0%)","0",IF(X2="2. Somewhat Compliant (25%)","25",IF(X2="3. Partially Compliant (50%)","50",IF(X2="4. Mostly Compliant (75%)","75",IF(X2="5. Fully Compliant (100%)","100"))))))<=32),"25",IF(AND((((_xlfn.XLOOKUP(Assessment!#REF!,Inherited!A:A,Inherited!B:B))/100)*(_xlfn.XLOOKUP(Assessment!#REF!,Inherited!A:A,Inherited!C:C)))+(((100-(_xlfn.XLOOKUP(Assessment!#REF!,Inherited!A:A,Inherited!B:B)))/100)*IF(X2="1. Non Compliant (0%)","0",IF(X2="2. Somewhat Compliant (25%)","25",IF(X2="3. Partially Compliant (50%)","50",IF(X2="4. Mostly Compliant (75%)","75",IF(X2="5. Fully Compliant (100%)","100"))))))>=33,(((_xlfn.XLOOKUP(Assessment!#REF!,Inherited!A:A,Inherited!B:B))/100)*(_xlfn.XLOOKUP(Assessment!#REF!,Inherited!A:A,Inherited!C:C)))+(((100-(_xlfn.XLOOKUP(Assessment!#REF!,Inherited!A:A,Inherited!B:B)))/100)*IF(X2="1. Non Compliant (0%)","0",IF(X2="2. Somewhat Compliant (25%)","25",IF(X2="3. Partially Compliant (50%)","50",IF(X2="4. Mostly Compliant (75%)","75",IF(X2="5. Fully Compliant (100%)","100"))))))<=65),"50",IF(AND((((_xlfn.XLOOKUP(Assessment!#REF!,Inherited!A:A,Inherited!B:B))/100)*(_xlfn.XLOOKUP(Assessment!#REF!,Inherited!A:A,Inherited!C:C)))+(((100-(_xlfn.XLOOKUP(Assessment!#REF!,Inherited!A:A,Inherited!B:B)))/100)*IF(X2="1. Non Compliant (0%)","0",IF(X2="2. Somewhat Compliant (25%)","25",IF(X2="3. Partially Compliant (50%)","50",IF(X2="4. Mostly Compliant (75%)","75",IF(X2="5. Fully Compliant (100%)","100"))))))>=66,(((_xlfn.XLOOKUP(Assessment!#REF!,Inherited!A:A,Inherited!B:B))/100)*(_xlfn.XLOOKUP(Assessment!#REF!,Inherited!A:A,Inherited!C:C)))+(((100-(_xlfn.XLOOKUP(Assessment!#REF!,Inherited!A:A,Inherited!B:B)))/100)*IF(X2="1. Non Compliant (0%)","0",IF(X2="2. Somewhat Compliant (25%)","25",IF(X2="3. Partially Compliant (50%)","50",IF(X2="4. Mostly Compliant (75%)","75",IF(X2="5. Fully Compliant (100%)","100"))))))<=89),"75",IF((((_xlfn.XLOOKUP(Assessment!#REF!,Inherited!A:A,Inherited!B:B))/100)*(_xlfn.XLOOKUP(Assessment!#REF!,Inherited!A:A,Inherited!C:C)))+(((100-(_xlfn.XLOOKUP(Assessment!#REF!,Inherited!A:A,Inherited!B:B)))/100)*IF(X2="1. Non Compliant (0%)","0",IF(X2="2. Somewhat Compliant (25%)","25",IF(X2="3. Partially Compliant (50%)","50",IF(X2="4. Mostly Compliant (75%)","75",IF(X2="5. Fully Compliant (100%)","100"))))))>=90,"100")))))) -> #N/A | R2: =IF(MATCH(H2,Inherited!A:A),IF((((_xlfn.XLOOKUP(Assessment!#REF!,Inherited!A:A,Inherited!B:B))/100)*(_xlfn.XLOOKUP(Assessment!#REF!,Inherited!A:A,Inherited!D:D)))+(((100-(_xlfn.XLOOKUP(Assessment!#REF!,Inherited!A:A,Inherited!B:B)))/100)*IF(Y2="1. Non Compliant (0%)","0",IF(Y2="2. Somewhat Compliant (25%)","25",IF(Y2="3. Partially Compliant (50%)","50",IF(Y2="4. Mostly Compliant (75%)","75",IF(Y2="5. Fully Compliant (100%)","100"))))))<=10,"0", IF(AND((((_xlfn.XLOOKUP(Assessment!#REF!,Inherited!A:A,Inherited!B:B))/100)*(_xlfn.XLOOKUP(Assessment!#REF!,Inherited!A:A,Inherited!D:D)))+(((100-(_xlfn.XLOOKUP(Assessment!#REF!,Inherited!A:A,Inherited!B:B)))/100)*IF(Y2="1. Non Compliant (0%)","0",IF(Y2="2. Somewhat Compliant (25%)","25",IF(Y2="3. Partially Compliant (50%)","50",IF(Y2="4. Mostly Compliant (75%)","75",IF(Y2="5. Fully Compliant (100%)","100"))))))>=11,(((_xlfn.XLOOKUP(Assessment!#REF!,Inherited!A:A,Inherited!B:B))/100)*(_xlfn.XLOOKUP(Assessment!#REF!,Inherited!A:A,Inherited!D:D)))+(((100-(_xlfn.XLOOKUP(Assessment!#REF!,Inherited!A:A,Inherited!B:B)))/100)*IF(Y2="1. Non Compliant (0%)","0",IF(Y2="2. Somewhat Compliant (25%)","25",IF(Y2="3. Partially Compliant (50%)","50",IF(Y2="4. Mostly Compliant (75%)","75",IF(Y2="5. Fully Compliant (100%)","100"))))))<=32),"25",IF(AND((((_xlfn.XLOOKUP(Assessment!#REF!,Inherited!A:A,Inherited!B:B))/100)*(_xlfn.XLOOKUP(Assessment!#REF!,Inherited!A:A,Inherited!D:D)))+(((100-(_xlfn.XLOOKUP(Assessment!#REF!,Inherited!A:A,Inherited!B:B)))/100)*IF(Y2="1. Non Compliant (0%)","0",IF(Y2="2. Somewhat Compliant (25%)","25",IF(Y2="3. Partially Compliant (50%)","50",IF(Y2="4. Mostly Compliant (75%)","75",IF(Y2="5. Fully Compliant (100%)","100"))))))>=33,(((_xlfn.XLOOKUP(Assessment!#REF!,Inherited!A:A,Inherited!B:B))/100)*(_xlfn.XLOOKUP(Assessment!#REF!,Inherited!A:A,Inherited!D:D)))+(((100-(_xlfn.XLOOKUP(Assessment!#REF!,Inherited!A:A,Inherited!B:B)))/100)*IF(Y2="1. Non Compliant (0%)","0",IF(Y2="2. Somewhat Compliant (25%)","25",IF(Y2="3. Partially Compliant (50%)","50",IF(Y2="4. Mostly Compliant (75%)","75",IF(Y2="5. Fully Compliant (100%)","100"))))))<=65),"50",IF(AND((((_xlfn.XLOOKUP(Assessment!#REF!,Inherited!A:A,Inherited!B:B))/100)*(_xlfn.XLOOKUP(Assessment!#REF!,Inherited!A:A,Inherited!D:D)))+(((100-(_xlfn.XLOOKUP(Assessment!#REF!,Inherited!A:A,Inherited!B:B)))/100)*IF(Y2="1. Non Compliant (0%)","0",IF(Y2="2. Somewhat Compliant (25%)","25",IF(Y2="3. Partially Compliant (50%)","50",IF(Y2="4. Mostly Compliant (75%)","75",IF(Y2="5. Fully Compliant (100%)","100"))))))>=66,(((_xlfn.XLOOKUP(Assessment!#REF!,Inherited!A:A,Inherited!B:B))/100)*(_xlfn.XLOOKUP(Assessment!#REF!,Inherited!A:A,Inherited!D:D)))+(((100-(_xlfn.XLOOKUP(Assessment!#REF!,Inherited!A:A,Inherited!B:B)))/100)*IF(Y2="1. Non Compliant (0%)","0",IF(Y2="2. Somewhat Compliant (25%)","25",IF(Y2="3. Partially Compliant (50%)","50",IF(Y2="4. Mostly Compliant (75%)","75",IF(Y2="5. Fully Compliant (100%)","100"))))))<=89),"75",IF((((_xlfn.XLOOKUP(Assessment!#REF!,Inherited!A:A,Inherited!B:B))/100)*(_xlfn.XLOOKUP(Assessment!#REF!,Inherited!A:A,Inherited!D:D)))+(((100-(_xlfn.XLOOKUP(Assessment!#REF!,Inherited!A:A,Inherited!B:B)))/100)*IF(Y2="1. Non Compliant (0%)","0",IF(Y2="2. Somewhat Compliant (25%)","25",IF(Y2="3. Partially Compliant (50%)","50",IF(Y2="4. Mostly Compliant (75%)","75",IF(Y2="5. Fully Compliant (100%)","100"))))))>=90,"100")))))) -> #N/A | S2: =IF(MATCH(H2,Inherited!A:A),IF((((_xlfn.XLOOKUP(Assessment!#REF!,Inherited!A:A,Inherited!B:B))/100)*(_xlfn.XLOOKUP(Assessment!#REF!,Inherited!A:A,Inherited!E:E)))+(((100-(_xlfn.XLOOKUP(Assessment!#REF!,Inherited!A:A,Inherited!B:B)))/100)*IF(Z2="1. Non Compliant (0%)","0",IF(Z2="2. Somewhat Compliant (25%)","25",IF(Z2="3. Partially Compliant (50%)","50",IF(Z2="4. Mostly Compliant (75%)","75",IF(Z2="5. Fully Compliant (100%)","100"))))))<=10,"0", IF(AND((((_xlfn.XLOOKUP(Assessment!#REF!,Inherited!A:A,Inherited!B:B))/100)*(_xlfn.XLOOKUP(Assessment!#REF!,Inherited!A:A,Inherited!E:E)))+(((100-(_xlfn.XLOOKUP(Assessment!#REF!,Inherited!A:A,Inherited!B:B)))/100)*IF(Z2="1. Non Compliant (0%)","0",IF(Z2="2. Somewhat Compliant (25%)","25",IF(Z2="3. Partially Compliant (50%)","50",IF(Z2="4. Mostly Compliant (75%)","75",IF(Z2="5. Fully Compliant (100%)","100"))))))>=11,(((_xlfn.XLOOKUP(Assessment!#REF!,Inherited!A:A,Inherited!B:B))/100)*(_xlfn.XLOOKUP(Assessment!#REF!,Inherited!A:A,Inherited!E:E)))+(((100-(_xlfn.XLOOKUP(Assessment!#REF!,Inherited!A:A,Inherited!B:B)))/100)*IF(Z2="1. Non Compliant (0%)","0",IF(Z2="2. Somewhat Compliant (25%)","25",IF(Z2="3. Partially Compliant (50%)","50",IF(Z2="4. Mostly Compliant (75%)","75",IF(Z2="5. Fully Compliant (100%)","100"))))))<=32),"25",IF(AND((((_xlfn.XLOOKUP(Assessment!#REF!,Inherited!A:A,Inherited!B:B))/100)*(_xlfn.XLOOKUP(Assessment!#REF!,Inherited!A:A,Inherited!E:E)))+(((100-(_xlfn.XLOOKUP(Assessment!#REF!,Inherited!A:A,Inherited!B:B)))/100)*IF(Z2="1. Non Compliant (0%)","0",IF(Z2="2. Somewhat Compliant (25%)","25",IF(Z2="3. Partially Compliant (50%)","50",IF(Z2="4. Mostly Compliant (75%)","75",IF(Z2="5. Fully Compliant (100%)","100"))))))>=33,(((_xlfn.XLOOKUP(Assessment!#REF!,Inherited!A:A,Inherited!B:B))/100)*(_xlfn.XLOOKUP(Assessment!#REF!,Inherited!A:A,Inherited!E:E)))+(((100-(_xlfn.XLOOKUP(Assessment!#REF!,Inherited!A:A,Inherited!B:B)))/100)*IF(Z2="1. Non Compliant (0%)","0",IF(Z2="2. Somewhat Compliant (25%)","25",IF(Z2="3. Partially Compliant (50%)","50",IF(Z2="4. Mostly Compliant (75%)","75",IF(Z2="5. Fully Compliant (100%)","100"))))))<=65),"50",IF(AND((((_xlfn.XLOOKUP(Assessment!#REF!,Inherited!A:A,Inherited!B:B))/100)*(_xlfn.XLOOKUP(Assessment!#REF!,Inherited!A:A,Inherited!E:E)))+(((100-(_xlfn.XLOOKUP(Assessment!#REF!,Inherited!A:A,Inherited!B:B)))/100)*IF(Z2="1. Non Compliant (0%)","0",IF(Z2="2. Somewhat Compliant (25%)","25",IF(Z2="3. Partially Compliant (50%)","50",IF(Z2="4. Mostly Compliant (75%)","75",IF(Z2="5. Fully Compliant (100%)","100"))))))>=66,(((_xlfn.XLOOKUP(Assessment!#REF!,Inherited!A:A,Inherited!B:B))/100)*(_xlfn.XLOOKUP(Assessment!#REF!,Inherited!A:A,Inherited!E:E)))+(((100-(_xlfn.XLOOKUP(Assessment!#REF!,Inherited!A:A,Inherited!B:B)))/100)*IF(Z2="1. Non Compliant (0%)","0",IF(Z2="2. Somewhat Compliant (25%)","25",IF(Z2="3. Partially Compliant (50%)","50",IF(Z2="4. Mostly Compliant (75%)","75",IF(Z2="5. Fully Compliant (100%)","100"))))))<=89),"75",IF((((_xlfn.XLOOKUP(Assessment!#REF!,Inherited!A:A,Inherited!B:B))/100)*(_xlfn.XLOOKUP(Assessment!#REF!,Inherited!A:A,Inherited!E:E)))+(((100-(_xlfn.XLOOKUP(Assessment!#REF!,Inherited!A:A,Inherited!B:B)))/100)*IF(Z2="1. Non Compliant (0%)","0",IF(Z2="2. Somewhat Compliant (25%)","25",IF(Z2="3. Partially Compliant (50%)","50",IF(Z2="4. Mostly Compliant (75%)","75",IF(Z2="5. Fully Compliant (100%)","100"))))))>=90,"100")))))) -> #N/A | T2: =IF(MATCH(H2,Inherited!A:A),IF((((_xlfn.XLOOKUP(Assessment!#REF!,Inherited!A:A,Inherited!B:B))/100)*(_xlfn.XLOOKUP(Assessment!#REF!,Inherited!A:A,Inherited!F:F)))+(((100-(_xlfn.XLOOKUP(Assessment!#REF!,Inherited!A:A,Inherited!B:B)))/100)*IF(AA2="1. Non Compliant (0%)","0",IF(AA2="2. Somewhat Compliant (25%)","25",IF(AA2="3. Partially Compliant (50%)","50",IF(AA2="4. Mostly Compliant (75%)","75",IF(AA2="5. Fully Compliant (100%)","100"))))))<=10,"0", IF(AND((((_xlfn.XLOOKUP(Assessment!#REF!,Inherited!A:A,Inherited!B:B))/100)*(_xlfn.XLOOKUP(Assessment!#REF!,Inherited!A:A,Inherited!F:F)))+(((100-(_xlfn.XLOOKUP(Assessment!#REF!,Inherited!A:A,Inherited!B:B)))/100)*IF(AA2="1. Non Compliant (0%)","0",IF(AA2="2. Somewhat Compliant (25%)","25",IF(AA2="3. Partially Compliant (50%)","50",IF(AA2="4. Mostly Compliant (75%)","75",IF(AA2="5. Fully Compliant (100%)","100"))))))>=11,(((_xlfn.XLOOKUP(Assessment!#REF!,Inherited!A:A,Inherited!B:B))/100)*(_xlfn.XLOOKUP(Assessment!#REF!,Inherited!A:A,Inherited!F:F)))+(((100-(_xlfn.XLOOKUP(Assessment!#REF!,Inherited!A:A,Inherited!B:B)))/100)*IF(AA2="1. Non Compliant (0%)","0",IF(AA2="2. Somewhat Compliant (25%)","25",IF(AA2="3. Partially Compliant (50%)","50",IF(AA2="4. Mostly Compliant (75%)","75",IF(AA2="5. Fully Compliant (100%)","100"))))))<=32),"25",IF(AND((((_xlfn.XLOOKUP(Assessment!#REF!,Inherited!A:A,Inherited!B:B))/100)*(_xlfn.XLOOKUP(Assessment!#REF!,Inherited!A:A,Inherited!F:F)))+(((100-(_xlfn.XLOOKUP(Assessment!#REF!,Inherited!A:A,Inherited!B:B)))/100)*IF(AA2="1. Non Compliant (0%)","0",IF(AA2="2. Somewhat Compliant (25%)","25",IF(AA2="3. Partially Compliant (50%)","50",IF(AA2="4. Mostly Compliant (75%)","75",IF(AA2="5. Fully Compliant (100%)","100"))))))>=33,(((_xlfn.XLOOKUP(Assessment!#REF!,Inherited!A:A,Inherited!B:B))/100)*(_xlfn.XLOOKUP(Assessment!#REF!,Inherited!A:A,Inherited!F:F)))+(((100-(_xlfn.XLOOKUP(Assessment!#REF!,Inherited!A:A,Inherited!B:B)))/100)*IF(AA2="1. Non Compliant (0%)","0",IF(AA2="2. Somewhat Compliant (25%)","25",IF(AA2="3. Partially Compliant (50%)","50",IF(AA2="4. Mostly Compliant (75%)","75",IF(AA2="5. Fully Compliant (100%)","100"))))))<=65),"50",IF(AND((((_xlfn.XLOOKUP(Assessment!#REF!,Inherited!A:A,Inherited!B:B))/100)*(_xlfn.XLOOKUP(Assessment!#REF!,Inherited!A:A,Inherited!F:F)))+(((100-(_xlfn.XLOOKUP(Assessment!#REF!,Inherited!A:A,Inherited!B:B)))/100)*IF(AA2="1. Non Compliant (0%)","0",IF(AA2="2. Somewhat Compliant (25%)","25",IF(AA2="3. Partially Compliant (50%)","50",IF(AA2="4. Mostly Compliant (75%)","75",IF(AA2="5. Fully Compliant (100%)","100"))))))>=66,(((_xlfn.XLOOKUP(Assessment!#REF!,Inherited!A:A,Inherited!B:B))/100)*(_xlfn.XLOOKUP(Assessment!#REF!,Inherited!A:A,Inherited!F:F)))+(((100-(_xlfn.XLOOKUP(Assessment!#REF!,Inherited!A:A,Inherited!B:B)))/100)*IF(AA2="1. Non Compliant (0%)","0",IF(AA2="2. Somewhat Compliant (25%)","25",IF(AA2="3. Partially Compliant (50%)","50",IF(AA2="4. Mostly Compliant (75%)","75",IF(AA2="5. Fully Compliant (100%)","100"))))))<=89),"75",IF((((_xlfn.XLOOKUP(Assessment!#REF!,Inherited!A:A,Inherited!B:B))/100)*(_xlfn.XLOOKUP(Assessment!#REF!,Inherited!A:A,Inherited!F:F)))+(((100-(_xlfn.XLOOKUP(Assessment!#REF!,Inherited!A:A,Inherited!B:B)))/100)*IF(AA2="1. Non Compliant (0%)","0",IF(AA2="2. Somewhat Compliant (25%)","25",IF(AA2="3. Partially Compliant (50%)","50",IF(AA2="4. Mostly Compliant (75%)","75",IF(AA2="5. Fully Compliant (100%)","100"))))))>=90,"100")))))) -> #N/A | U2: =IF(MATCH(H2,Inherited!A:A),IF((((_xlfn.XLOOKUP(Assessment!#REF!,Inherited!A:A,Inherited!B:B))/100)*(_xlfn.XLOOKUP(Assessment!#REF!,Inherited!A:A,Inherited!G:G)))+(((100-(_xlfn.XLOOKUP(Assessment!#REF!,Inherited!A:A,Inherited!B:B)))/100)*IF(AB2="1. Non Compliant (0%)","0",IF(AB2="2. Somewhat Compliant (25%)","25",IF(AB2="3. Partially Compliant (50%)","50",IF(AB2="4. Mostly Compliant (75%)","75",IF(AB2="5. Fully Compliant (100%)","100"))))))<=10,"0", IF(AND((((_xlfn.XLOOKUP(Assessment!#REF!,Inherited!A:A,Inherited!B:B))/100)*(_xlfn.XLOOKUP(Assessment!#REF!,Inherited!A:A,Inherited!G:G)))+(((100-(_xlfn.XLOOKUP(Assessment!#REF!,Inherited!A:A,Inherited!B:B)))/100)*IF(AB2="1. Non Compliant (0%)","0",IF(AB2="2. Somewhat Compliant (25%)","25",IF(AB2="3. Partially Compliant (50%)","50",IF(AB2="4. Mostly Compliant (75%)","75",IF(AB2="5. Fully Compliant (100%)","100"))))))>=11,(((_xlfn.XLOOKUP(Assessment!#REF!,Inherited!A:A,Inherited!B:B))/100)*(_xlfn.XLOOKUP(Assessment!#REF!,Inherited!A:A,Inherited!G:G)))+(((100-(_xlfn.XLOOKUP(Assessment!#REF!,Inherited!A:A,Inherited!B:B)))/100)*IF(AB2="1. Non Compliant (0%)","0",IF(AB2="2. Somewhat Compliant (25%)","25",IF(AB2="3. Partially Compliant (50%)","50",IF(AB2="4. Mostly Compliant (75%)","75",IF(AB2="5. Fully Compliant (100%)","100"))))))<=32),"25",IF(AND((((_xlfn.XLOOKUP(Assessment!#REF!,Inherited!A:A,Inherited!B:B))/100)*(_xlfn.XLOOKUP(Assessment!#REF!,Inherited!A:A,Inherited!G:G)))+(((100-(_xlfn.XLOOKUP(Assessment!#REF!,Inherited!A:A,Inherited!B:B)))/100)*IF(AB2="1. Non Compliant (0%)","0",IF(AB2="2. Somewhat Compliant (25%)","25",IF(AB2="3. Partially Compliant (50%)","50",IF(AB2="4. Mostly Compliant (75%)","75",IF(AB2="5. Fully Compliant (100%)","100"))))))>=33,(((_xlfn.XLOOKUP(Assessment!#REF!,Inherited!A:A,Inherited!B:B))/100)*(_xlfn.XLOOKUP(Assessment!#REF!,Inherited!A:A,Inherited!G:G)))+(((100-(_xlfn.XLOOKUP(Assessment!#REF!,Inherited!A:A,Inherited!B:B)))/100)*IF(AB2="1. Non Compliant (0%)","0",IF(AB2="2. Somewhat Compliant (25%)","25",IF(AB2="3. Partially Compliant (50%)","50",IF(AB2="4. Mostly Compliant (75%)","75",IF(AB2="5. Fully Compliant (100%)","100"))))))<=65),"50",IF(AND((((_xlfn.XLOOKUP(Assessment!#REF!,Inherited!A:A,Inherited!B:B))/100)*(_xlfn.XLOOKUP(Assessment!#REF!,Inherited!A:A,Inherited!G:G)))+(((100-(_xlfn.XLOOKUP(Assessment!#REF!,Inherited!A:A,Inherited!B:B)))/100)*IF(AB2="1. Non Compliant (0%)","0",IF(AB2="2. Somewhat Compliant (25%)","25",IF(AB2="3. Partially Compliant (50%)","50",IF(AB2="4. Mostly Compliant (75%)","75",IF(AB2="5. Fully Compliant (100%)","100"))))))>=66,(((_xlfn.XLOOKUP(Assessment!#REF!,Inherited!A:A,Inherited!B:B))/100)*(_xlfn.XLOOKUP(Assessment!#REF!,Inherited!A:A,Inherited!G:G)))+(((100-(_xlfn.XLOOKUP(Assessment!#REF!,Inherited!A:A,Inherited!B:B)))/100)*IF(AB2="1. Non Compliant (0%)","0",IF(AB2="2. Somewhat Compliant (25%)","25",IF(AB2="3. Partially Compliant (50%)","50",IF(AB2="4. Mostly Compliant (75%)","75",IF(AB2="5. Fully Compliant (100%)","100"))))))<=89),"75",IF((((_xlfn.XLOOKUP(Assessment!#REF!,Inherited!A:A,Inherited!B:B))/100)*(_xlfn.XLOOKUP(Assessment!#REF!,Inherited!A:A,Inherited!G:G)))+(((100-(_xlfn.XLOOKUP(Assessment!#REF!,Inherited!A:A,Inherited!B:B)))/100)*IF(AB2="1. Non Compliant (0%)","0",IF(AB2="2. Somewhat Compliant (25%)","25",IF(AB2="3. Partially Compliant (50%)","50",IF(AB2="4. Mostly Compliant (75%)","75",IF(AB2="5. Fully Compliant (100%)","100"))))))>=90,"100")))))) -> #N/A | V2: Yes | Z2: 1. Non Compliant (0%) | AK2: Michael Wood - VP of AI Engineering Kyle Smith - IT Operations and AI Expert | AL2: AI policies and procedures are not formally maintained at this time. Documentation will be developed and integrated to existing Merge policies and procedures | AP2: Gap: AI policies and procedures considering the details of the requirement statement are not formally maintained at this time. Recommendation: Management should ensure that AI policies and procedures are developed considering the following: - defines: security administration - defines: data governance - defines: software development - defines: risk management - defines: incident management - defines: business continuity - defines: disaster recovery | AX2: =_xlfn.CONCAT("A-LIGN finished its review of this control on ",AR2, " during the scheduled fieldwork window (",Intro!$B$4,")."& CHAR(10)& CHAR(10)) -> A-LIGN finished its review of this control on during the scheduled fieldwork window (Fieldwork: xx/xx/xxxx - xx/xx/xxxx). | AY2: =IF(AQ2<>"",(_xlfn.CONCAT("Inheritance note: "& CHAR(10),AQ2& CHAR(10)& CHAR(10))),"") | AZ2: =IFERROR(IF(AD2<>"",_xlfn.CONCAT("Examined the following policy during fieldwork:"& CHAR(10),AD2& CHAR(10)& CHAR(10),IF(AND(X2<>"5. Fully Compliant (100%)",AE2<>""),"Reviewed policy exception note:"& CHAR(10) & AE2 & CHAR(10) & CHAR(10),"")),""),"") | BA2: =IFERROR(IF(AH2<>"",_xlfn.CONCAT("Examined the following process during fieldwork:"& CHAR(10),AH2& CHAR(10)& CHAR(10),IF(AND(Y2<>"5. Fully Compliant (100%)",AI2<>""),"Reviewed process exception note:"& CHAR(10) & AI2 & CHAR(10) & CHAR(10),"")),""),"") | BB2: =IF(AK2<>"",(_xlfn.CONCAT("Inquired of the following workforce member: "& CHAR(10),AK2& CHAR(10)& CHAR(10),"Inquiry lead to the following conclusions: "& CHAR(10),AL2& CHAR(10) & CHAR(10))),"") -> Inquired of the following workforce member: Michael Wood - VP of AI Engineering Kyle Smith - IT Operations and AI Expert Inquiry lead to the following conclusions: AI policies and procedures are not formally maintained at this time. Documentation will be developed and integrated to existing Merge policies and procedures | BC2: =IF(AM2<>"",(_xlfn.CONCAT("Observed the following live during fieldwork: "& CHAR(10),AM2& CHAR(10) & CHAR(10))),"") | BD2: =_xlfn.CONCAT("Examined the following evidence during fieldwork:"& CHAR(10),AN2& CHAR(10)& CHAR(10),IF(AO2<>"","Reviewed evidence note:"& CHAR(10)&AO2& CHAR(10) & CHAR(10),"Reviewed evidence addressed the requirement statement."& CHAR(10) & CHAR(10)),IF(AND(AP2<>"5. Fully Compliant (100%)",AP2<>""),"Reviewed evidence exception note: "& CHAR(10) & AP2 & CHAR(10) & CHAR(10),"")) -> Examined the following evidence during fieldwork: Reviewed evidence addressed the requirement statement. Reviewed evidence exception note: Gap: AI policies and procedures considering the details of the requirement statement are not formally maintained at this time. Recommendation: Management should ensure that AI policies and procedures are developed considering the following: - defines: security administration - defines: data governance - defines: software development - defines: risk management - defines: incident management - defines: business continuity - defines: disaster recovery | BE2: =IF(AT2<>"",(_xlfn.CONCAT("Examined the following measure/metric during fieldwork:"& CHAR(10),AT2& CHAR(10)& CHAR(10),"Reviewed measure/metric note:"& CHAR(10),AU2 & CHAR(10) & CHAR(10))),"") | BF2: =IF(AV2<>"",(_xlfn.CONCAT("Examined the following measure/metric management during fieldwork:"& CHAR(10),AV2& CHAR(10)& CHAR(10),"Reviewed measure/metric management note:"& CHAR(10),AW2 & CHAR(10) & CHAR(10))),"") | BG2: =_xlfn.CONCAT((IF((COUNTIF('Sample Tables'!B:B,"")>0)=TRUE,_xlfn.CONCAT("",""),IF((COUNTIF('Sample Tables'!B:B,"")>0)=FALSE,""))),) | BH2: =IF(V2="No","Not Applicable: "&W2,(_xlfn.CONCAT(AX2,AY2,AZ2,BA2,BB2,BC2,BD2,BE2,BF2,BG2))) -> A-LIGN finished its review of this control on during the scheduled fieldwork window (Fieldwork: xx/xx/xxxx - xx/xx/xxxx). Inquired of the following workforce member: Michael Wood - VP of AI Engineering Kyle Smith - IT Operations and AI Expert Inquiry lead to the following conclusions: AI policies and procedures are not formally maintained at this time. Documentation will be developed and integrated to existing Merge policies and procedures Examined the following evidence during fieldwork: Reviewed evidence addressed the requirement statement. Reviewed evidence exception note: Gap: AI policies and procedures considering the details of the requirement statement are not formally maintained at this time. Recommendation: Management should ensure that AI policies and procedures are developed considering the following: - defines: security administration - defines: data governance - defines: software development - defines: risk management - defines: incident management - defines: business continuity - defines: disaster recovery
C3: =IF(V3="No","Not Applicable",(IF(X3="1. Non Compliant (0%)","0",IF(X3="2. Somewhat Compliant (25%)","25",IF(X3="3. Partially Compliant (50%)","50",IF(X3="4. Mostly Compliant (75%)","75",IF(X3="5. Fully Compliant (100%)","100")))))*0.15)+((IF(Y3="1. Non Compliant (0%)","0",IF(Y3="2. Somewhat Compliant (25%)","25",IF(Y3="3. Partially Compliant (50%)","50",IF(Y3="4. Mostly Compliant (75%)","75",IF(Y3="5. Fully Compliant (100%)","100"))))))*0.2)+(IF(Z3="1. Non Compliant (0%)","0",IF(Z3="2. Somewhat Compliant (25%)","25",IF(Z3="3. Partially Compliant (50%)","50",IF(Z3="4. Mostly Compliant (75%)","75",IF(Z3="5. Fully Compliant (100%)","100")))))*0.4)+(IF(AA3="1. Non Compliant (0%)","0",IF(AA3="2. Somewhat Compliant (25%)","25",IF(AA3="3. Partially Compliant (50%)","50",IF(AA3="4. Mostly Compliant (75%)","75",IF(AA3="5. Fully Compliant (100%)","100")))))*0.1)+(IF(AB3="1. Non Compliant (0%)","0",IF(AB3="2. Somewhat Compliant (25%)","25",IF(AB3="3. Partially Compliant (50%)","50",IF(AB3="4. Mostly Compliant (75%)","75",IF(AB3="5. Fully Compliant (100%)","100")))))*0.15)) -> 0 | D3: =IF(AND((_xlfn.XLOOKUP(J3,'Fields & Revisions'!$H:$H,'Fields & Revisions'!$I:$I))<70.99,(OR(Z3="4. Mostly Compliant (75%)",Z3="3. Partially Compliant (50%)",Z3="2. Somewhat Compliant (25%)",Z3="1. Non Compliant (0%)"))),"Yes","No") -> Yes | E3: =IF(ISERROR(VLOOKUP(H3,Scope!A:A,1,FALSE)),"No","Yes") -> Yes | F3: 01 Information Protection Program | G3: 3037.0 | H3: 01.02aAISecOrganizational.1 | I3: HITRUST Security for AI System | J3: 02.a Roles and Responsibilities | K3: The organization formally defines the roles and responsibilities for the |governance, |security, and |risk management|| of the organization's deployed AI systems within the organization (e.g., by extending a pre-existing RACI chart or creating a new one specific to AI).|| The organization formally |assigns human accountability for the actions performed by, outputs produced by, and decisions made by the organization’s deployed AI systems.|| | L3: Examine evidence that all evaluative elements within the requirement statement have been implemented as defined in the HITRUST scoring rubric, using a sample based test where possible for each evaluative element. Example test(s): For example, review AI systems policy and procedure documentation to determine if roles and responsibilities for the governance, security, and risk management of the organization’s deployed AI systems is in place. Further, confirm that the organization assigns human accountability for the actions performed by, outputs produced by, and decisions made by the organization’s deployed AI systems. | M3: Documentation: Artificial Intelligence Program - defines: roles and responsibilities for governance - defines: roles and responsibilities for security - defines: roles and responsibilities for risk management Evidence Test: Artificial Intelligence - human accountability assigned for actions performed by the Artificial Intelligence System - human accountability assigned for outputs produced by the Artificial Intelligence System - human accountability assigned for decisions made by the Artificial Intelligence System | N3: No | O3: =_xlfn.XLOOKUP(G3,SRMs!$A:$A,SRMs!$D:$D) -> NO INHERITANCE | P3: =IFERROR(VLOOKUP(H3,Inherited!A:B,2,FALSE),"") | Q3: =IF(MATCH(H3,Inherited!A:A),IF((((_xlfn.XLOOKUP(Assessment!#REF!,Inherited!A:A,Inherited!B:B))/100)*(_xlfn.XLOOKUP(Assessment!#REF!,Inherited!A:A,Inherited!C:C)))+(((100-(_xlfn.XLOOKUP(Assessment!#REF!,Inherited!A:A,Inherited!B:B)))/100)*IF(X3="1. Non Compliant (0%)","0",IF(X3="2. Somewhat Compliant (25%)","25",IF(X3="3. Partially Compliant (50%)","50",IF(X3="4. Mostly Compliant (75%)","75",IF(X3="5. Fully Compliant (100%)","100"))))))<=10,"0", IF(AND((((_xlfn.XLOOKUP(Assessment!#REF!,Inherited!A:A,Inherited!B:B))/100)*(_xlfn.XLOOKUP(Assessment!#REF!,Inherited!A:A,Inherited!C:C)))+(((100-(_xlfn.XLOOKUP(Assessment!#REF!,Inherited!A:A,Inherited!B:B)))/100)*IF(X3="1. Non Compliant (0%)","0",IF(X3="2. Somewhat Compliant (25%)","25",IF(X3="3. Partially Compliant (50%)","50",IF(X3="4. Mostly Compliant (75%)","75",IF(X3="5. Fully Compliant (100%)","100"))))))>=11,(((_xlfn.XLOOKUP(Assessment!#REF!,Inherited!A:A,Inherited!B:B))/100)*(_xlfn.XLOOKUP(Assessment!#REF!,Inherited!A:A,Inherited!C:C)))+(((100-(_xlfn.XLOOKUP(Assessment!#REF!,Inherited!A:A,Inherited!B:B)))/100)*IF(X3="1. Non Compliant (0%)","0",IF(X3="2. Somewhat Compliant (25%)","25",IF(X3="3. Partially Compliant (50%)","50",IF(X3="4. Mostly Compliant (75%)","75",IF(X3="5. Fully Compliant (100%)","100"))))))<=32),"25",IF(AND((((_xlfn.XLOOKUP(Assessment!#REF!,Inherited!A:A,Inherited!B:B))/100)*(_xlfn.XLOOKUP(Assessment!#REF!,Inherited!A:A,Inherited!C:C)))+(((100-(_xlfn.XLOOKUP(Assessment!#REF!,Inherited!A:A,Inherited!B:B)))/100)*IF(X3="1. Non Compliant (0%)","0",IF(X3="2. Somewhat Compliant (25%)","25",IF(X3="3. Partially Compliant (50%)","50",IF(X3="4. Mostly Compliant (75%)","75",IF(X3="5. Fully Compliant (100%)","100"))))))>=33,(((_xlfn.XLOOKUP(Assessment!#REF!,Inherited!A:A,Inherited!B:B))/100)*(_xlfn.XLOOKUP(Assessment!#REF!,Inherited!A:A,Inherited!C:C)))+(((100-(_xlfn.XLOOKUP(Assessment!#REF!,Inherited!A:A,Inherited!B:B)))/100)*IF(X3="1. Non Compliant (0%)","0",IF(X3="2. Somewhat Compliant (25%)","25",IF(X3="3. Partially Compliant (50%)","50",IF(X3="4. Mostly Compliant (75%)","75",IF(X3="5. Fully Compliant (100%)","100"))))))<=65),"50",IF(AND((((_xlfn.XLOOKUP(Assessment!#REF!,Inherited!A:A,Inherited!B:B))/100)*(_xlfn.XLOOKUP(Assessment!#REF!,Inherited!A:A,Inherited!C:C)))+(((100-(_xlfn.XLOOKUP(Assessment!#REF!,Inherited!A:A,Inherited!B:B)))/100)*IF(X3="1. Non Compliant (0%)","0",IF(X3="2. Somewhat Compliant (25%)","25",IF(X3="3. Partially Compliant (50%)","50",IF(X3="4. Mostly Compliant (75%)","75",IF(X3="5. Fully Compliant (100%)","100"))))))>=66,(((_xlfn.XLOOKUP(Assessment!#REF!,Inherited!A:A,Inherited!B:B))/100)*(_xlfn.XLOOKUP(Assessment!#REF!,Inherited!A:A,Inherited!C:C)))+(((100-(_xlfn.XLOOKUP(Assessment!#REF!,Inherited!A:A,Inherited!B:B)))/100)*IF(X3="1. Non Compliant (0%)","0",IF(X3="2. Somewhat Compliant (25%)","25",IF(X3="3. Partially Compliant (50%)","50",IF(X3="4. Mostly Compliant (75%)","75",IF(X3="5. Fully Compliant (100%)","100"))))))<=89),"75",IF((((_xlfn.XLOOKUP(Assessment!#REF!,Inherited!A:A,Inherited!B:B))/100)*(_xlfn.XLOOKUP(Assessment!#REF!,Inherited!A:A,Inherited!C:C)))+(((100-(_xlfn.XLOOKUP(Assessment!#REF!,Inherited!A:A,Inherited!B:B)))/100)*IF(X3="1. Non Compliant (0%)","0",IF(X3="2. Somewhat Compliant (25%)","25",IF(X3="3. Partially Compliant (50%)","50",IF(X3="4. Mostly Compliant (75%)","75",IF(X3="5. Fully Compliant (100%)","100"))))))>=90,"100")))))) -> #N/A | R3: =IF(MATCH(H3,Inherited!A:A),IF((((_xlfn.XLOOKUP(Assessment!#REF!,Inherited!A:A,Inherited!B:B))/100)*(_xlfn.XLOOKUP(Assessment!#REF!,Inherited!A:A,Inherited!D:D)))+(((100-(_xlfn.XLOOKUP(Assessment!#REF!,Inherited!A:A,Inherited!B:B)))/100)*IF(Y3="1. Non Compliant (0%)","0",IF(Y3="2. Somewhat Compliant (25%)","25",IF(Y3="3. Partially Compliant (50%)","50",IF(Y3="4. Mostly Compliant (75%)","75",IF(Y3="5. Fully Compliant (100%)","100"))))))<=10,"0", IF(AND((((_xlfn.XLOOKUP(Assessment!#REF!,Inherited!A:A,Inherited!B:B))/100)*(_xlfn.XLOOKUP(Assessment!#REF!,Inherited!A:A,Inherited!D:D)))+(((100-(_xlfn.XLOOKUP(Assessment!#REF!,Inherited!A:A,Inherited!B:B)))/100)*IF(Y3="1. Non Compliant (0%)","0",IF(Y3="2. Somewhat Compliant (25%)","25",IF(Y3="3. Partially Compliant (50%)","50",IF(Y3="4. Mostly Compliant (75%)","75",IF(Y3="5. Fully Compliant (100%)","100"))))))>=11,(((_xlfn.XLOOKUP(Assessment!#REF!,Inherited!A:A,Inherited!B:B))/100)*(_xlfn.XLOOKUP(Assessment!#REF!,Inherited!A:A,Inherited!D:D)))+(((100-(_xlfn.XLOOKUP(Assessment!#REF!,Inherited!A:A,Inherited!B:B)))/100)*IF(Y3="1. Non Compliant (0%)","0",IF(Y3="2. Somewhat Compliant (25%)","25",IF(Y3="3. Partially Compliant (50%)","50",IF(Y3="4. Mostly Compliant (75%)","75",IF(Y3="5. Fully Compliant (100%)","100"))))))<=32),"25",IF(AND((((_xlfn.XLOOKUP(Assessment!#REF!,Inherited!A:A,Inherited!B:B))/100)*(_xlfn.XLOOKUP(Assessment!#REF!,Inherited!A:A,Inherited!D:D)))+(((100-(_xlfn.XLOOKUP(Assessment!#REF!,Inherited!A:A,Inherited!B:B)))/100)*IF(Y3="1. Non Compliant (0%)","0",IF(Y3="2. Somewhat Compliant (25%)","25",IF(Y3="3. Partially Compliant (50%)","50",IF(Y3="4. Mostly Compliant (75%)","75",IF(Y3="5. Fully Compliant (100%)","100"))))))>=33,(((_xlfn.XLOOKUP(Assessment!#REF!,Inherited!A:A,Inherited!B:B))/100)*(_xlfn.XLOOKUP(Assessment!#REF!,Inherited!A:A,Inherited!D:D)))+(((100-(_xlfn.XLOOKUP(Assessment!#REF!,Inherited!A:A,Inherited!B:B)))/100)*IF(Y3="1. Non Compliant (0%)","0",IF(Y3="2. Somewhat Compliant (25%)","25",IF(Y3="3. Partially Compliant (50%)","50",IF(Y3="4. Mostly Compliant (75%)","75",IF(Y3="5. Fully Compliant (100%)","100"))))))<=65),"50",IF(AND((((_xlfn.XLOOKUP(Assessment!#REF!,Inherited!A:A,Inherited!B:B))/100)*(_xlfn.XLOOKUP(Assessment!#REF!,Inherited!A:A,Inherited!D:D)))+(((100-(_xlfn.XLOOKUP(Assessment!#REF!,Inherited!A:A,Inherited!B:B)))/100)*IF(Y3="1. Non Compliant (0%)","0",IF(Y3="2. Somewhat Compliant (25%)","25",IF(Y3="3. Partially Compliant (50%)","50",IF(Y3="4. Mostly Compliant (75%)","75",IF(Y3="5. Fully Compliant (100%)","100"))))))>=66,(((_xlfn.XLOOKUP(Assessment!#REF!,Inherited!A:A,Inherited!B:B))/100)*(_xlfn.XLOOKUP(Assessment!#REF!,Inherited!A:A,Inherited!D:D)))+(((100-(_xlfn.XLOOKUP(Assessment!#REF!,Inherited!A:A,Inherited!B:B)))/100)*IF(Y3="1. Non Compliant (0%)","0",IF(Y3="2. Somewhat Compliant (25%)","25",IF(Y3="3. Partially Compliant (50%)","50",IF(Y3="4. Mostly Compliant (75%)","75",IF(Y3="5. Fully Compliant (100%)","100"))))))<=89),"75",IF((((_xlfn.XLOOKUP(Assessment!#REF!,Inherited!A:A,Inherited!B:B))/100)*(_xlfn.XLOOKUP(Assessment!#REF!,Inherited!A:A,Inherited!D:D)))+(((100-(_xlfn.XLOOKUP(Assessment!#REF!,Inherited!A:A,Inherited!B:B)))/100)*IF(Y3="1. Non Compliant (0%)","0",IF(Y3="2. Somewhat Compliant (25%)","25",IF(Y3="3. Partially Compliant (50%)","50",IF(Y3="4. Mostly Compliant (75%)","75",IF(Y3="5. Fully Compliant (100%)","100"))))))>=90,"100")))))) -> #N/A | S3: =IF(MATCH(H3,Inherited!A:A),IF((((_xlfn.XLOOKUP(Assessment!#REF!,Inherited!A:A,Inherited!B:B))/100)*(_xlfn.XLOOKUP(Assessment!#REF!,Inherited!A:A,Inherited!E:E)))+(((100-(_xlfn.XLOOKUP(Assessment!#REF!,Inherited!A:A,Inherited!B:B)))/100)*IF(Z3="1. Non Compliant (0%)","0",IF(Z3="2. Somewhat Compliant (25%)","25",IF(Z3="3. Partially Compliant (50%)","50",IF(Z3="4. Mostly Compliant (75%)","75",IF(Z3="5. Fully Compliant (100%)","100"))))))<=10,"0", IF(AND((((_xlfn.XLOOKUP(Assessment!#REF!,Inherited!A:A,Inherited!B:B))/100)*(_xlfn.XLOOKUP(Assessment!#REF!,Inherited!A:A,Inherited!E:E)))+(((100-(_xlfn.XLOOKUP(Assessment!#REF!,Inherited!A:A,Inherited!B:B)))/100)*IF(Z3="1. Non Compliant (0%)","0",IF(Z3="2. Somewhat Compliant (25%)","25",IF(Z3="3. Partially Compliant (50%)","50",IF(Z3="4. Mostly Compliant (75%)","75",IF(Z3="5. Fully Compliant (100%)","100"))))))>=11,(((_xlfn.XLOOKUP(Assessment!#REF!,Inherited!A:A,Inherited!B:B))/100)*(_xlfn.XLOOKUP(Assessment!#REF!,Inherited!A:A,Inherited!E:E)))+(((100-(_xlfn.XLOOKUP(Assessment!#REF!,Inherited!A:A,Inherited!B:B)))/100)*IF(Z3="1. Non Compliant (0%)","0",IF(Z3="2. Somewhat Compliant (25%)","25",IF(Z3="3. Partially Compliant (50%)","50",IF(Z3="4. Mostly Compliant (75%)","75",IF(Z3="5. Fully Compliant (100%)","100"))))))<=32),"25",IF(AND((((_xlfn.XLOOKUP(Assessment!#REF!,Inherited!A:A,Inherited!B:B))/100)*(_xlfn.XLOOKUP(Assessment!#REF!,Inherited!A:A,Inherited!E:E)))+(((100-(_xlfn.XLOOKUP(Assessment!#REF!,Inherited!A:A,Inherited!B:B)))/100)*IF(Z3="1. Non Compliant (0%)","0",IF(Z3="2. Somewhat Compliant (25%)","25",IF(Z3="3. Partially Compliant (50%)","50",IF(Z3="4. Mostly Compliant (75%)","75",IF(Z3="5. Fully Compliant (100%)","100"))))))>=33,(((_xlfn.XLOOKUP(Assessment!#REF!,Inherited!A:A,Inherited!B:B))/100)*(_xlfn.XLOOKUP(Assessment!#REF!,Inherited!A:A,Inherited!E:E)))+(((100-(_xlfn.XLOOKUP(Assessment!#REF!,Inherited!A:A,Inherited!B:B)))/100)*IF(Z3="1. Non Compliant (0%)","0",IF(Z3="2. Somewhat Compliant (25%)","25",IF(Z3="3. Partially Compliant (50%)","50",IF(Z3="4. Mostly Compliant (75%)","75",IF(Z3="5. Fully Compliant (100%)","100"))))))<=65),"50",IF(AND((((_xlfn.XLOOKUP(Assessment!#REF!,Inherited!A:A,Inherited!B:B))/100)*(_xlfn.XLOOKUP(Assessment!#REF!,Inherited!A:A,Inherited!E:E)))+(((100-(_xlfn.XLOOKUP(Assessment!#REF!,Inherited!A:A,Inherited!B:B)))/100)*IF(Z3="1. Non Compliant (0%)","0",IF(Z3="2. Somewhat Compliant (25%)","25",IF(Z3="3. Partially Compliant (50%)","50",IF(Z3="4. Mostly Compliant (75%)","75",IF(Z3="5. Fully Compliant (100%)","100"))))))>=66,(((_xlfn.XLOOKUP(Assessment!#REF!,Inherited!A:A,Inherited!B:B))/100)*(_xlfn.XLOOKUP(Assessment!#REF!,Inherited!A:A,Inherited!E:E)))+(((100-(_xlfn.XLOOKUP(Assessment!#REF!,Inherited!A:A,Inherited!B:B)))/100)*IF(Z3="1. Non Compliant (0%)","0",IF(Z3="2. Somewhat Compliant (25%)","25",IF(Z3="3. Partially Compliant (50%)","50",IF(Z3="4. Mostly Compliant (75%)","75",IF(Z3="5. Fully Compliant (100%)","100"))))))<=89),"75",IF((((_xlfn.XLOOKUP(Assessment!#REF!,Inherited!A:A,Inherited!B:B))/100)*(_xlfn.XLOOKUP(Assessment!#REF!,Inherited!A:A,Inherited!E:E)))+(((100-(_xlfn.XLOOKUP(Assessment!#REF!,Inherited!A:A,Inherited!B:B)))/100)*IF(Z3="1. Non Compliant (0%)","0",IF(Z3="2. Somewhat Compliant (25%)","25",IF(Z3="3. Partially Compliant (50%)","50",IF(Z3="4. Mostly Compliant (75%)","75",IF(Z3="5. Fully Compliant (100%)","100"))))))>=90,"100")))))) -> #N/A | T3: =IF(MATCH(H3,Inherited!A:A),IF((((_xlfn.XLOOKUP(Assessment!#REF!,Inherited!A:A,Inherited!B:B))/100)*(_xlfn.XLOOKUP(Assessment!#REF!,Inherited!A:A,Inherited!F:F)))+(((100-(_xlfn.XLOOKUP(Assessment!#REF!,Inherited!A:A,Inherited!B:B)))/100)*IF(AA3="1. Non Compliant (0%)","0",IF(AA3="2. Somewhat Compliant (25%)","25",IF(AA3="3. Partially Compliant (50%)","50",IF(AA3="4. Mostly Compliant (75%)","75",IF(AA3="5. Fully Compliant (100%)","100"))))))<=10,"0", IF(AND((((_xlfn.XLOOKUP(Assessment!#REF!,Inherited!A:A,Inherited!B:B))/100)*(_xlfn.XLOOKUP(Assessment!#REF!,Inherited!A:A,Inherited!F:F)))+(((100-(_xlfn.XLOOKUP(Assessment!#REF!,Inherited!A:A,Inherited!B:B)))/100)*IF(AA3="1. Non Compliant (0%)","0",IF(AA3="2. Somewhat Compliant (25%)","25",IF(AA3="3. Partially Compliant (50%)","50",IF(AA3="4. Mostly Compliant (75%)","75",IF(AA3="5. Fully Compliant (100%)","100"))))))>=11,(((_xlfn.XLOOKUP(Assessment!#REF!,Inherited!A:A,Inherited!B:B))/100)*(_xlfn.XLOOKUP(Assessment!#REF!,Inherited!A:A,Inherited!F:F)))+(((100-(_xlfn.XLOOKUP(Assessment!#REF!,Inherited!A:A,Inherited!B:B)))/100)*IF(AA3="1. Non Compliant (0%)","0",IF(AA3="2. Somewhat Compliant (25%)","25",IF(AA3="3. Partially Compliant (50%)","50",IF(AA3="4. Mostly Compliant (75%)","75",IF(AA3="5. Fully Compliant (100%)","100"))))))<=32),"25",IF(AND((((_xlfn.XLOOKUP(Assessment!#REF!,Inherited!A:A,Inherited!B:B))/100)*(_xlfn.XLOOKUP(Assessment!#REF!,Inherited!A:A,Inherited!F:F)))+(((100-(_xlfn.XLOOKUP(Assessment!#REF!,Inherited!A:A,Inherited!B:B)))/100)*IF(AA3="1. Non Compliant (0%)","0",IF(AA3="2. Somewhat Compliant (25%)","25",IF(AA3="3. Partially Compliant (50%)","50",IF(AA3="4. Mostly Compliant (75%)","75",IF(AA3="5. Fully Compliant (100%)","100"))))))>=33,(((_xlfn.XLOOKUP(Assessment!#REF!,Inherited!A:A,Inherited!B:B))/100)*(_xlfn.XLOOKUP(Assessment!#REF!,Inherited!A:A,Inherited!F:F)))+(((100-(_xlfn.XLOOKUP(Assessment!#REF!,Inherited!A:A,Inherited!B:B)))/100)*IF(AA3="1. Non Compliant (0%)","0",IF(AA3="2. Somewhat Compliant (25%)","25",IF(AA3="3. Partially Compliant (50%)","50",IF(AA3="4. Mostly Compliant (75%)","75",IF(AA3="5. Fully Compliant (100%)","100"))))))<=65),"50",IF(AND((((_xlfn.XLOOKUP(Assessment!#REF!,Inherited!A:A,Inherited!B:B))/100)*(_xlfn.XLOOKUP(Assessment!#REF!,Inherited!A:A,Inherited!F:F)))+(((100-(_xlfn.XLOOKUP(Assessment!#REF!,Inherited!A:A,Inherited!B:B)))/100)*IF(AA3="1. Non Compliant (0%)","0",IF(AA3="2. Somewhat Compliant (25%)","25",IF(AA3="3. Partially Compliant (50%)","50",IF(AA3="4. Mostly Compliant (75%)","75",IF(AA3="5. Fully Compliant (100%)","100"))))))>=66,(((_xlfn.XLOOKUP(Assessment!#REF!,Inherited!A:A,Inherited!B:B))/100)*(_xlfn.XLOOKUP(Assessment!#REF!,Inherited!A:A,Inherited!F:F)))+(((100-(_xlfn.XLOOKUP(Assessment!#REF!,Inherited!A:A,Inherited!B:B)))/100)*IF(AA3="1. Non Compliant (0%)","0",IF(AA3="2. Somewhat Compliant (25%)","25",IF(AA3="3. Partially Compliant (50%)","50",IF(AA3="4. Mostly Compliant (75%)","75",IF(AA3="5. Fully Compliant (100%)","100"))))))<=89),"75",IF((((_xlfn.XLOOKUP(Assessment!#REF!,Inherited!A:A,Inherited!B:B))/100)*(_xlfn.XLOOKUP(Assessment!#REF!,Inherited!A:A,Inherited!F:F)))+(((100-(_xlfn.XLOOKUP(Assessment!#REF!,Inherited!A:A,Inherited!B:B)))/100)*IF(AA3="1. Non Compliant (0%)","0",IF(AA3="2. Somewhat Compliant (25%)","25",IF(AA3="3. Partially Compliant (50%)","50",IF(AA3="4. Mostly Compliant (75%)","75",IF(AA3="5. Fully Compliant (100%)","100"))))))>=90,"100")))))) -> #N/A | U3: =IF(MATCH(H3,Inherited!A:A),IF((((_xlfn.XLOOKUP(Assessment!#REF!,Inherited!A:A,Inherited!B:B))/100)*(_xlfn.XLOOKUP(Assessment!#REF!,Inherited!A:A,Inherited!G:G)))+(((100-(_xlfn.XLOOKUP(Assessment!#REF!,Inherited!A:A,Inherited!B:B)))/100)*IF(AB3="1. Non Compliant (0%)","0",IF(AB3="2. Somewhat Compliant (25%)","25",IF(AB3="3. Partially Compliant (50%)","50",IF(AB3="4. Mostly Compliant (75%)","75",IF(AB3="5. Fully Compliant (100%)","100"))))))<=10,"0", IF(AND((((_xlfn.XLOOKUP(Assessment!#REF!,Inherited!A:A,Inherited!B:B))/100)*(_xlfn.XLOOKUP(Assessment!#REF!,Inherited!A:A,Inherited!G:G)))+(((100-(_xlfn.XLOOKUP(Assessment!#REF!,Inherited!A:A,Inherited!B:B)))/100)*IF(AB3="1. Non Compliant (0%)","0",IF(AB3="2. Somewhat Compliant (25%)","25",IF(AB3="3. Partially Compliant (50%)","50",IF(AB3="4. Mostly Compliant (75%)","75",IF(AB3="5. Fully Compliant (100%)","100"))))))>=11,(((_xlfn.XLOOKUP(Assessment!#REF!,Inherited!A:A,Inherited!B:B))/100)*(_xlfn.XLOOKUP(Assessment!#REF!,Inherited!A:A,Inherited!G:G)))+(((100-(_xlfn.XLOOKUP(Assessment!#REF!,Inherited!A:A,Inherited!B:B)))/100)*IF(AB3="1. Non Compliant (0%)","0",IF(AB3="2. Somewhat Compliant (25%)","25",IF(AB3="3. Partially Compliant (50%)","50",IF(AB3="4. Mostly Compliant (75%)","75",IF(AB3="5. Fully Compliant (100%)","100"))))))<=32),"25",IF(AND((((_xlfn.XLOOKUP(Assessment!#REF!,Inherited!A:A,Inherited!B:B))/100)*(_xlfn.XLOOKUP(Assessment!#REF!,Inherited!A:A,Inherited!G:G)))+(((100-(_xlfn.XLOOKUP(Assessment!#REF!,Inherited!A:A,Inherited!B:B)))/100)*IF(AB3="1. Non Compliant (0%)","0",IF(AB3="2. Somewhat Compliant (25%)","25",IF(AB3="3. Partially Compliant (50%)","50",IF(AB3="4. Mostly Compliant (75%)","75",IF(AB3="5. Fully Compliant (100%)","100"))))))>=33,(((_xlfn.XLOOKUP(Assessment!#REF!,Inherited!A:A,Inherited!B:B))/100)*(_xlfn.XLOOKUP(Assessment!#REF!,Inherited!A:A,Inherited!G:G)))+(((100-(_xlfn.XLOOKUP(Assessment!#REF!,Inherited!A:A,Inherited!B:B)))/100)*IF(AB3="1. Non Compliant (0%)","0",IF(AB3="2. Somewhat Compliant (25%)","25",IF(AB3="3. Partially Compliant (50%)","50",IF(AB3="4. Mostly Compliant (75%)","75",IF(AB3="5. Fully Compliant (100%)","100"))))))<=65),"50",IF(AND((((_xlfn.XLOOKUP(Assessment!#REF!,Inherited!A:A,Inherited!B:B))/100)*(_xlfn.XLOOKUP(Assessment!#REF!,Inherited!A:A,Inherited!G:G)))+(((100-(_xlfn.XLOOKUP(Assessment!#REF!,Inherited!A:A,Inherited!B:B)))/100)*IF(AB3="1. Non Compliant (0%)","0",IF(AB3="2. Somewhat Compliant (25%)","25",IF(AB3="3. Partially Compliant (50%)","50",IF(AB3="4. Mostly Compliant (75%)","75",IF(AB3="5. Fully Compliant (100%)","100"))))))>=66,(((_xlfn.XLOOKUP(Assessment!#REF!,Inherited!A:A,Inherited!B:B))/100)*(_xlfn.XLOOKUP(Assessment!#REF!,Inherited!A:A,Inherited!G:G)))+(((100-(_xlfn.XLOOKUP(Assessment!#REF!,Inherited!A:A,Inherited!B:B)))/100)*IF(AB3="1. Non Compliant (0%)","0",IF(AB3="2. Somewhat Compliant (25%)","25",IF(AB3="3. Partially Compliant (50%)","50",IF(AB3="4. Mostly Compliant (75%)","75",IF(AB3="5. Fully Compliant (100%)","100"))))))<=89),"75",IF((((_xlfn.XLOOKUP(Assessment!#REF!,Inherited!A:A,Inherited!B:B))/100)*(_xlfn.XLOOKUP(Assessment!#REF!,Inherited!A:A,Inherited!G:G)))+(((100-(_xlfn.XLOOKUP(Assessment!#REF!,Inherited!A:A,Inherited!B:B)))/100)*IF(AB3="1. Non Compliant (0%)","0",IF(AB3="2. Somewhat Compliant (25%)","25",IF(AB3="3. Partially Compliant (50%)","50",IF(AB3="4. Mostly Compliant (75%)","75",IF(AB3="5. Fully Compliant (100%)","100"))))))>=90,"100")))))) -> #N/A | V3: Yes | Z3: 1. Non Compliant (0%) | AK3: Michael Wood - VP of AI Engineering Kyle Smith - IT Operations and AI Expert | AL3: AI policies and procedures are not formally maintained at this time. Documentation will be developed and integrated to existing Merge policies and procedures | AP3: Gap: AI policies and procedures considering the details of the requirement statement are not formally maintained at this time. Recommendation: Management should ensure that AI policies and procedures are developed considering the following: - defines: roles and responsibilities for governance - defines: roles and responsibilities for security - defines: roles and responsibilities for risk management Further, management should ensure that the organization assigns human accountability for the actions performed by, outputs produced by, and decisions made by the organization’s deployed AI systems. | AX3: =_xlfn.CONCAT("A-LIGN finished its review of this control on ",AR3, " during the scheduled fieldwork window (",Intro!$B$4,")."& CHAR(10)& CHAR(10)) -> A-LIGN finished its review of this control on during the scheduled fieldwork window (Fieldwork: xx/xx/xxxx - xx/xx/xxxx). | AY3: =IF(AQ3<>"",(_xlfn.CONCAT("Inheritance note: "& CHAR(10),AQ3& CHAR(10)& CHAR(10))),"") | AZ3: =IFERROR(IF(AD3<>"",_xlfn.CONCAT("Examined the following policy during fieldwork:"& CHAR(10),AD3& CHAR(10)& CHAR(10),IF(AND(X3<>"5. Fully Compliant (100%)",AE3<>""),"Reviewed policy exception note:"& CHAR(10) & AE3 & CHAR(10) & CHAR(10),"")),""),"") | BA3: =IFERROR(IF(AH3<>"",_xlfn.CONCAT("Examined the following process during fieldwork:"& CHAR(10),AH3& CHAR(10)& CHAR(10),IF(AND(Y3<>"5. Fully Compliant (100%)",AI3<>""),"Reviewed process exception note:"& CHAR(10) & AI3 & CHAR(10) & CHAR(10),"")),""),"") | BB3: =IF(AK3<>"",(_xlfn.CONCAT("Inquired of the following workforce member: "& CHAR(10),AK3& CHAR(10)& CHAR(10),"Inquiry lead to the following conclusions: "& CHAR(10),AL3& CHAR(10) & CHAR(10))),"") -> Inquired of the following workforce member: Michael Wood - VP of AI Engineering Kyle Smith - IT Operations and AI Expert Inquiry lead to the following conclusions: AI policies and procedures are not formally maintained at this time. Documentation will be developed and integrated to existing Merge policies and procedures | BC3: =IF(AM3<>"",(_xlfn.CONCAT("Observed the following live during fieldwork: "& CHAR(10),AM3& CHAR(10) & CHAR(10))),"") | BD3: =_xlfn.CONCAT("Examined the following evidence during fieldwork:"& CHAR(10),AN3& CHAR(10)& CHAR(10),IF(AO3<>"","Reviewed evidence note:"& CHAR(10)&AO3& CHAR(10) & CHAR(10),"Reviewed evidence addressed the requirement statement."& CHAR(10) & CHAR(10)),IF(AND(AP3<>"5. Fully Compliant (100%)",AP3<>""),"Reviewed evidence exception note: "& CHAR(10) & AP3 & CHAR(10) & CHAR(10),"")) -> Examined the following evidence during fieldwork: Reviewed evidence addressed the requirement statement. Reviewed evidence exception note: Gap: AI policies and procedures considering the details of the requirement statement are not formally maintained at this time. Recommendation: Management should ensure that AI policies and procedures are developed considering the following: - defines: roles and responsibilities for governance - defines: roles and responsibilities for security - defines: roles and responsibilities for risk management Further, management should ensure that the organization assigns human accountability for the actions performed by, outputs produced by, and decisions made by the organization’s deployed AI systems. | BE3: =IF(AT3<>"",(_xlfn.CONCAT("Examined the following measure/metric during fieldwork:"& CHAR(10),AT3& CHAR(10)& CHAR(10),"Reviewed measure/metric note:"& CHAR(10),AU3 & CHAR(10) & CHAR(10))),"") | BF3: =IF(AV3<>"",(_xlfn.CONCAT("Examined the following measure/metric management during fieldwork:"& CHAR(10),AV3& CHAR(10)& CHAR(10),"Reviewed measure/metric management note:"& CHAR(10),AW3 & CHAR(10) & CHAR(10))),"") | BG3: =_xlfn.CONCAT((IF((COUNTIF('Sample Tables'!B:B,"")>0)=TRUE,_xlfn.CONCAT("",""),IF((COUNTIF('Sample Tables'!B:B,"")>0)=FALSE,""))),) | BH3: =IF(V3="No","Not Applicable: "&W3,(_xlfn.CONCAT(AX3,AY3,AZ3,BA3,BB3,BC3,BD3,BE3,BF3,BG3))) -> A-LIGN finished its review of this control on during the scheduled fieldwork window (Fieldwork: xx/xx/xxxx - xx/xx/xxxx). Inquired of the following workforce member: Michael Wood - VP of AI Engineering Kyle Smith - IT Operations and AI Expert Inquiry lead to the following conclusions: AI policies and procedures are not formally maintained at this time. Documentation will be developed and integrated to existing Merge policies and procedures Examined the following evidence during fieldwork: Reviewed evidence addressed the requirement statement. Reviewed evidence exception note: Gap: AI policies and procedures considering the details of the requirement statement are not formally maintained at this time. Recommendation: Management should ensure that AI policies and procedures are developed considering the following: - defines: roles and responsibilities for governance - defines: roles and responsibilities for security - defines: roles and responsibilities for risk management Further, management should ensure that the organization assigns human accountability for the actions performed by, outputs produced by, and decisions made by the organization’s deployed AI systems.
